# Exception Handlind simple demo

try :
    print(x)
except :
    print('an exception occurred')


# The try block will generation, because 'x' is not defined
