# Exception handling with finally block

try :
    print(x)

except :
    print('Something went wrong')

finally :
    print("The 'try except' is finished")

# The 'finally' block, if specified will executed regardless if the try block raise an error or not
